apiVersion: openapi/v1alpha1
kind: Radar
metadata:
    name: "21707972"
    labels:
        datastore_id: "6118465387626496"
data:
    classification: Serious Bug
    created: "2015-07-07T18:30:04.89121Z"
    description: "Summary:\r\nOne can throw a specific enum ErrorType, and be unable to catch it:\r\n\r\nimport XCTest\r\n\r\nclass Context {\r\n}\r\n\r\nenum LostError : ErrorType {\r\n    case A(Context)\r\n    case B(Context)\r\n}\r\n\r\nclass LostErrorTests: XCTestCase {\r\n    func testLostError() {\r\n        do {\r\n            throw LostError.B(Context())\r\n        } catch LostError.B {\r\n            // OK: B expected\r\n        } catch LostError.A {\r\n            XCTFail(\"Expected B\")      <--- Fail\r\n        } catch {\r\n            // OK: B expected\r\n        }\r\n    }\r\n}\r\n\r\nSteps to Reproduce:\r\nRun the code above.\r\n\r\nExpected Results:\r\n The caught error should be LostError.B\r\n\r\nActual Results:\r\n The caught error is LostError.A\r\n\r\nVersion:\r\nXcode 7.0 beta (7A121l)\r\nOSX 10.10.3 (14D136)\r\n\r\nNotes:\r\nRemove the Context from case A, and the test pass.\r\n\r\n  enum LostError : ErrorType {\r\n-     case A(Context)\r\n+    case A\r\n      case B(Context)\r\n  }"
    email: gwendal.roue@gmail.com
    modified: "2015-07-07T18:30:04.89154Z"
    number: "21707972"
    number_intvalue: 21707972
    originated: "2015-07-07"
    parent_number: '&{NULL_VALUE}'
    product: Developer Tools
    product_version: Xcode 7.0 beta (7A121l)
    reproducible: Always
    resolved: ""
    status: Open
    title: 'Swift 2: enum ErrorType with attached Class lose their type'
